22/Mar/2023 11:10:24 ERROR /Users/ugolkov/Desktop/News_Portal/venv/lib/python3.10/site-packages/django/utils/log.py Internal Server Error: /news/create/ (<class 'ValueError'>, ValueError('Cannot assign "<django.db.models.query_utils.DeferredAttribute object at 0x1070f3f40>": "Post.author" must be a "Author" instance.'), <traceback object at 0x107ea1440>)
Traceback (most recent call last):
  File "/Users/ugolkov/Desktop/News_Portal/venv/lib/python3.10/site-packages/django/core/handlers/exception.py", line 55, in inner
    response = get_response(request)
  File "/Users/ugolkov/Desktop/News_Portal/venv/lib/python3.10/site-packages/django/core/handlers/base.py", line 197, in _get_response
    response = wrapped_callback(request, *callback_args, **callback_kwargs)
  File "/Users/ugolkov/Desktop/News_Portal/venv/lib/python3.10/site-packages/django/views/generic/base.py", line 103, in view
    return self.dispatch(request, *args, **kwargs)
  File "/Users/ugolkov/Desktop/News_Portal/venv/lib/python3.10/site-packages/django/contrib/auth/mixins.py", line 109, in dispatch
    return super().dispatch(request, *args, **kwargs)
  File "/Users/ugolkov/Desktop/News_Portal/venv/lib/python3.10/site-packages/django/views/generic/base.py", line 142, in dispatch
    return handler(request, *args, **kwargs)
  File "/Users/ugolkov/Desktop/News_Portal/venv/lib/python3.10/site-packages/django/views/generic/edit.py", line 184, in post
    return super().post(request, *args, **kwargs)
  File "/Users/ugolkov/Desktop/News_Portal/venv/lib/python3.10/site-packages/django/views/generic/edit.py", line 153, in post
    return self.form_valid(form)
  File "/Users/ugolkov/Desktop/News_Portal/NewsPortal/news/views.py", line 60, in form_valid
    post.author = User.username
  File "/Users/ugolkov/Desktop/News_Portal/venv/lib/python3.10/site-packages/django/db/models/fields/related_descriptors.py", line 237, in __set__
    raise ValueError(
ValueError: Cannot assign "<django.db.models.query_utils.DeferredAttribute object at 0x1070f3f40>": "Post.author" must be a "Author" instance.
22/Mar/2023 11:10:24 ERROR /Users/ugolkov/Desktop/News_Portal/venv/lib/python3.10/site-packages/django/core/servers/basehttp.py "POST /news/create/ HTTP/1.1" 500 93872 None
22/Mar/2023 11:13:41 ERROR /Users/ugolkov/Desktop/News_Portal/venv/lib/python3.10/site-packages/django/utils/log.py Internal Server Error: /news/create/ (<class 'django.db.utils.IntegrityError'>, IntegrityError('NOT NULL constraint failed: news_post.author_id'), <traceback object at 0x1039b6a80>)
Traceback (most recent call last):
  File "/Users/ugolkov/Desktop/News_Portal/venv/lib/python3.10/site-packages/django/db/backends/utils.py", line 89, in _execute
    return self.cursor.execute(sql, params)
  File "/Users/ugolkov/Desktop/News_Portal/venv/lib/python3.10/site-packages/django/db/backends/sqlite3/base.py", line 357, in execute
    return Database.Cursor.execute(self, query, params)
sqlite3.IntegrityError: NOT NULL constraint failed: news_post.author_id

The above exception was the direct cause of the following exception:

Traceback (most recent call last):
  File "/Users/ugolkov/Desktop/News_Portal/venv/lib/python3.10/site-packages/django/core/handlers/exception.py", line 55, in inner
    response = get_response(request)
  File "/Users/ugolkov/Desktop/News_Portal/venv/lib/python3.10/site-packages/django/core/handlers/base.py", line 197, in _get_response
    response = wrapped_callback(request, *callback_args, **callback_kwargs)
  File "/Users/ugolkov/Desktop/News_Portal/venv/lib/python3.10/site-packages/django/views/generic/base.py", line 103, in view
    return self.dispatch(request, *args, **kwargs)
  File "/Users/ugolkov/Desktop/News_Portal/venv/lib/python3.10/site-packages/django/contrib/auth/mixins.py", line 109, in dispatch
    return super().dispatch(request, *args, **kwargs)
  File "/Users/ugolkov/Desktop/News_Portal/venv/lib/python3.10/site-packages/django/views/generic/base.py", line 142, in dispatch
    return handler(request, *args, **kwargs)
  File "/Users/ugolkov/Desktop/News_Portal/venv/lib/python3.10/site-packages/django/views/generic/edit.py", line 184, in post
    return super().post(request, *args, **kwargs)
  File "/Users/ugolkov/Desktop/News_Portal/venv/lib/python3.10/site-packages/django/views/generic/edit.py", line 153, in post
    return self.form_valid(form)
  File "/Users/ugolkov/Desktop/News_Portal/NewsPortal/news/views.py", line 62, in form_valid
    post.save()
  File "/Users/ugolkov/Desktop/News_Portal/venv/lib/python3.10/site-packages/django/db/models/base.py", line 812, in save
    self.save_base(
  File "/Users/ugolkov/Desktop/News_Portal/venv/lib/python3.10/site-packages/django/db/models/base.py", line 863, in save_base
    updated = self._save_table(
  File "/Users/ugolkov/Desktop/News_Portal/venv/lib/python3.10/site-packages/django/db/models/base.py", line 1006, in _save_table
    results = self._do_insert(
  File "/Users/ugolkov/Desktop/News_Portal/venv/lib/python3.10/site-packages/django/db/models/base.py", line 1047, in _do_insert
    return manager._insert(
  File "/Users/ugolkov/Desktop/News_Portal/venv/lib/python3.10/site-packages/django/db/models/manager.py", line 85, in manager_method
    return getattr(self.get_queryset(), name)(*args, **kwargs)
  File "/Users/ugolkov/Desktop/News_Portal/venv/lib/python3.10/site-packages/django/db/models/query.py", line 1791, in _insert
    return query.get_compiler(using=using).execute_sql(returning_fields)
  File "/Users/ugolkov/Desktop/News_Portal/venv/lib/python3.10/site-packages/django/db/models/sql/compiler.py", line 1660, in execute_sql
    cursor.execute(sql, params)
  File "/Users/ugolkov/Desktop/News_Portal/venv/lib/python3.10/site-packages/django/db/backends/utils.py", line 103, in execute
    return super().execute(sql, params)
  File "/Users/ugolkov/Desktop/News_Portal/venv/lib/python3.10/site-packages/django/db/backends/utils.py", line 67, in execute
    return self._execute_with_wrappers(
  File "/Users/ugolkov/Desktop/News_Portal/venv/lib/python3.10/site-packages/django/db/backends/utils.py", line 80, in _execute_with_wrappers
    return executor(sql, params, many, context)
  File "/Users/ugolkov/Desktop/News_Portal/venv/lib/python3.10/site-packages/django/db/backends/utils.py", line 84, in _execute
    with self.db.wrap_database_errors:
  File "/Users/ugolkov/Desktop/News_Portal/venv/lib/python3.10/site-packages/django/db/utils.py", line 91, in __exit__
    raise dj_exc_value.with_traceback(traceback) from exc_value
  File "/Users/ugolkov/Desktop/News_Portal/venv/lib/python3.10/site-packages/django/db/backends/utils.py", line 89, in _execute
    return self.cursor.execute(sql, params)
  File "/Users/ugolkov/Desktop/News_Portal/venv/lib/python3.10/site-packages/django/db/backends/sqlite3/base.py", line 357, in execute
    return Database.Cursor.execute(self, query, params)
django.db.utils.IntegrityError: NOT NULL constraint failed: news_post.author_id
22/Mar/2023 11:13:41 ERROR /Users/ugolkov/Desktop/News_Portal/venv/lib/python3.10/site-packages/django/core/servers/basehttp.py "POST /news/create/ HTTP/1.1" 500 174225 None
22/Mar/2023 11:17:01 ERROR /Users/ugolkov/Desktop/News_Portal/venv/lib/python3.10/site-packages/django/utils/log.py Internal Server Error: /news/create/ (<class 'django.contrib.auth.models.User.MultipleObjectsReturned'>, MultipleObjectsReturned('get() returned more than one User -- it returned 5!'), <traceback object at 0x1053d3ac0>)
Traceback (most recent call last):
  File "/Users/ugolkov/Desktop/News_Portal/venv/lib/python3.10/site-packages/django/core/handlers/exception.py", line 55, in inner
    response = get_response(request)
  File "/Users/ugolkov/Desktop/News_Portal/venv/lib/python3.10/site-packages/django/core/handlers/base.py", line 197, in _get_response
    response = wrapped_callback(request, *callback_args, **callback_kwargs)
  File "/Users/ugolkov/Desktop/News_Portal/venv/lib/python3.10/site-packages/django/views/generic/base.py", line 103, in view
    return self.dispatch(request, *args, **kwargs)
  File "/Users/ugolkov/Desktop/News_Portal/venv/lib/python3.10/site-packages/django/contrib/auth/mixins.py", line 109, in dispatch
    return super().dispatch(request, *args, **kwargs)
  File "/Users/ugolkov/Desktop/News_Portal/venv/lib/python3.10/site-packages/django/views/generic/base.py", line 142, in dispatch
    return handler(request, *args, **kwargs)
  File "/Users/ugolkov/Desktop/News_Portal/venv/lib/python3.10/site-packages/django/views/generic/edit.py", line 184, in post
    return super().post(request, *args, **kwargs)
  File "/Users/ugolkov/Desktop/News_Portal/venv/lib/python3.10/site-packages/django/views/generic/edit.py", line 153, in post
    return self.form_valid(form)
  File "/Users/ugolkov/Desktop/News_Portal/NewsPortal/news/views.py", line 54, in form_valid
    print(User.objects.get())
  File "/Users/ugolkov/Desktop/News_Portal/venv/lib/python3.10/site-packages/django/db/models/manager.py", line 85, in manager_method
    return getattr(self.get_queryset(), name)(*args, **kwargs)
  File "/Users/ugolkov/Desktop/News_Portal/venv/lib/python3.10/site-packages/django/db/models/query.py", line 653, in get
    raise self.model.MultipleObjectsReturned(
django.contrib.auth.models.User.MultipleObjectsReturned: get() returned more than one User -- it returned 5!
22/Mar/2023 11:17:01 ERROR /Users/ugolkov/Desktop/News_Portal/venv/lib/python3.10/site-packages/django/core/servers/basehttp.py "POST /news/create/ HTTP/1.1" 500 97749 None
22/Mar/2023 11:20:05 ERROR /Users/ugolkov/Desktop/News_Portal/venv/lib/python3.10/site-packages/django/utils/log.py Internal Server Error: /news/create/ (<class 'smtplib.SMTPAuthenticationError'>, SMTPAuthenticationError(535, b'5.7.8 Error: authentication failed: Invalid user or password! 1679484005-3KoHSO0cvW21'), <traceback object at 0x1030afb40>)
Traceback (most recent call last):
  File "/Users/ugolkov/Desktop/News_Portal/venv/lib/python3.10/site-packages/django/core/handlers/exception.py", line 55, in inner
    response = get_response(request)
  File "/Users/ugolkov/Desktop/News_Portal/venv/lib/python3.10/site-packages/django/core/handlers/base.py", line 197, in _get_response
    response = wrapped_callback(request, *callback_args, **callback_kwargs)
  File "/Users/ugolkov/Desktop/News_Portal/venv/lib/python3.10/site-packages/django/views/generic/base.py", line 103, in view
    return self.dispatch(request, *args, **kwargs)
  File "/Users/ugolkov/Desktop/News_Portal/venv/lib/python3.10/site-packages/django/contrib/auth/mixins.py", line 109, in dispatch
    return super().dispatch(request, *args, **kwargs)
  File "/Users/ugolkov/Desktop/News_Portal/venv/lib/python3.10/site-packages/django/views/generic/base.py", line 142, in dispatch
    return handler(request, *args, **kwargs)
  File "/Users/ugolkov/Desktop/News_Portal/venv/lib/python3.10/site-packages/django/views/generic/edit.py", line 184, in post
    return super().post(request, *args, **kwargs)
  File "/Users/ugolkov/Desktop/News_Portal/venv/lib/python3.10/site-packages/django/views/generic/edit.py", line 153, in post
    return self.form_valid(form)
  File "/Users/ugolkov/Desktop/News_Portal/NewsPortal/news/views.py", line 62, in form_valid
    return super().form_valid(form)
  File "/Users/ugolkov/Desktop/News_Portal/venv/lib/python3.10/site-packages/django/views/generic/edit.py", line 135, in form_valid
    self.object = form.save()
  File "/Users/ugolkov/Desktop/News_Portal/venv/lib/python3.10/site-packages/django/forms/models.py", line 549, in save
    self._save_m2m()
  File "/Users/ugolkov/Desktop/News_Portal/venv/lib/python3.10/site-packages/django/forms/models.py", line 530, in _save_m2m
    f.save_form_data(self.instance, cleaned_data[f.name])
  File "/Users/ugolkov/Desktop/News_Portal/venv/lib/python3.10/site-packages/django/db/models/fields/related.py", line 1966, in save_form_data
    getattr(instance, self.attname).set(data)
  File "/Users/ugolkov/Desktop/News_Portal/venv/lib/python3.10/site-packages/django/db/models/fields/related_descriptors.py", line 1169, in set
    self.add(*new_objs, through_defaults=through_defaults)
  File "/Users/ugolkov/Desktop/News_Portal/venv/lib/python3.10/site-packages/django/db/models/fields/related_descriptors.py", line 1087, in add
    self._add_items(
  File "/Users/ugolkov/Desktop/News_Portal/venv/lib/python3.10/site-packages/django/db/models/fields/related_descriptors.py", line 1373, in _add_items
    signals.m2m_changed.send(
  File "/Users/ugolkov/Desktop/News_Portal/venv/lib/python3.10/site-packages/django/dispatch/dispatcher.py", line 176, in send
    return [
  File "/Users/ugolkov/Desktop/News_Portal/venv/lib/python3.10/site-packages/django/dispatch/dispatcher.py", line 177, in <listcomp>
    (receiver, receiver(signal=self, sender=sender, **named))
  File "/Users/ugolkov/Desktop/News_Portal/NewsPortal/news/signals.py", line 40, in notify_about_new_post
    send_notifications(instance.text, instance.pk, instance.title, subscribes_emails)
  File "/Users/ugolkov/Desktop/News_Portal/NewsPortal/news/signals.py", line 27, in send_notifications
    msg.send()
  File "/Users/ugolkov/Desktop/News_Portal/venv/lib/python3.10/site-packages/django/core/mail/message.py", line 298, in send
    return self.get_connection(fail_silently).send_messages([self])
  File "/Users/ugolkov/Desktop/News_Portal/venv/lib/python3.10/site-packages/django/core/mail/backends/smtp.py", line 124, in send_messages
    new_conn_created = self.open()
  File "/Users/ugolkov/Desktop/News_Portal/venv/lib/python3.10/site-packages/django/core/mail/backends/smtp.py", line 91, in open
    self.connection.login(self.username, self.password)
  File "/Library/Frameworks/Python.framework/Versions/3.10/lib/python3.10/smtplib.py", line 750, in login
    raise last_exception
  File "/Library/Frameworks/Python.framework/Versions/3.10/lib/python3.10/smtplib.py", line 739, in login
    (code, resp) = self.auth(
  File "/Library/Frameworks/Python.framework/Versions/3.10/lib/python3.10/smtplib.py", line 662, in auth
    raise SMTPAuthenticationError(code, resp)
smtplib.SMTPAuthenticationError: (535, b'5.7.8 Error: authentication failed: Invalid user or password! 1679484005-3KoHSO0cvW21')
22/Mar/2023 11:20:05 ERROR /Users/ugolkov/Desktop/News_Portal/venv/lib/python3.10/site-packages/django/core/servers/basehttp.py "POST /news/create/ HTTP/1.1" 500 166255 None
